<?xml version="1.0" encoding="utf-8"?>
<robot name="GEN3_URDF_V12" version="1.0" path="../ros_kortex/kortex_description/arms/gen3/7dof/urdf/GEN3_URDF_V12.urdf">
	<link name="base_link">
		<inertial>
			<origin xyz="-0.000648 -0.000166 0.084487" rpy="0 0 0"></origin>
			<mass value="1.697"></mass>
			<inertia ixx="0.004622" ixy="9E-06" ixz="6E-05" iyy="0.004495" iyz="9E-06" izz="0.002079"></inertia>
		</inertial>
		<visual>
			<origin xyz="0 0 0" rpy="0 0 0"></origin>
			<geometry>
				<mesh filename="../meshes/base_link.STL"></mesh>
			</geometry>
			<material name="">
				<color rgba="0.75294 0.75294 0.75294 1"></color>
			</material>
		</visual>
		<collision>
			<geometry>
				<sphere radius="0.104568"></sphere>
			</geometry>
			<origin xyz="-0.0009214775421330004 0.00012720666306155243 0.0845244901283652" rpy="0 0 0"></origin>
		</collision>
	</link>
	<link name="Shoulder_Link">
		<inertial>
			<origin xyz="-2.3E-05 -0.010364 -0.07336" rpy="0 0 0"></origin>
			<mass value="1.3773"></mass>
			<inertia ixx="0.00457" ixy="1E-06" ixz="2E-06" iyy="0.004831" iyz="0.000448" izz="0.001409"></inertia>
		</inertial>
		<visual>
			<origin xyz="0 0 0" rpy="0 0 0"></origin>
			<geometry>
				<mesh filename="../meshes/shoulder_link.STL"></mesh>
			</geometry>
			<material name="">
				<color rgba="0.75294 0.75294 0.75294 1"></color>
			</material>
		</visual>
		<collision>
			<geometry>
				<sphere radius="0.101375"></sphere>
			</geometry>
			<origin xyz="0.0072466835953777795 -0.01297839423177411 -0.0818534780888557" rpy="0 0 0"></origin>
		</collision>
	</link>
	<link name="HalfArm1_Link">
		<inertial>
			<origin xyz="-4.4E-05 -0.09958 -0.013278" rpy="0 0 0"></origin>
			<mass value="1.1636"></mass>
			<inertia ixx="0.011088" ixy="5E-06" ixz="0" iyy="0.001072" iyz="-0.000691" izz="0.011255"></inertia>
		</inertial>
		<visual>
			<origin xyz="0 0 0" rpy="0 0 0"></origin>
			<geometry>
				<mesh filename="../meshes/half_arm_1_link.STL"></mesh>
			</geometry>
			<material name="">
				<color rgba="0.75294 0.75294 0.75294 1"></color>
			</material>
		</visual>
		<collision>
			<geometry>
				<sphere radius="0.146811"></sphere>
			</geometry>
			<origin xyz="0.0009441554989579898 -0.09419298276866789 -0.02012095819762487" rpy="0 0 0"></origin>
		</collision>
	</link>
	<link name="HalfArm2_Link">
		<inertial>
			<origin xyz="-4.4E-05 -0.006641 -0.117892" rpy="0 0 0"></origin>
			<mass value="1.1636"></mass>
			<inertia ixx="0.010932" ixy="0" ixz="-7E-06" iyy="0.011127" iyz="0.000606" izz="0.001043"></inertia>
		</inertial>
		<visual>
			<origin xyz="0 0 0" rpy="0 0 0"></origin>
			<geometry>
				<mesh filename="../meshes/half_arm_2_link.STL"></mesh>
			</geometry>
			<material name="">
				<color rgba="0.75294 0.75294 0.75294 1"></color>
			</material>
		</visual>
		<collision>
			<geometry>
				<sphere radius="0.139798"></sphere>
			</geometry>
			<origin xyz="0.0006371918486141393 -0.01689509275333136 -0.12469023751050672" rpy="0 0 0"></origin>
		</collision>
	</link>
	<link name="ForeArm_Link">
		<inertial>
			<origin xyz="-1.8E-05 -0.075478 -0.015006" rpy="0 0 0"></origin>
			<mass value="0.9302"></mass>
			<inertia ixx="0.008147" ixy="-1E-06" ixz="0" iyy="0.000631" iyz="-0.0005" izz="0.008316"></inertia>
		</inertial>
		<visual>
			<origin xyz="0 0 0" rpy="0 0 0"></origin>
			<geometry>
				<mesh filename="../meshes/forearm_link.STL"></mesh>
			</geometry>
			<material name="">
				<color rgba="0.75294 0.75294 0.75294 1"></color>
			</material>
		</visual>
		<collision>
			<geometry>
				<sphere radius="0.142848"></sphere>
			</geometry>
			<origin xyz="0.0009144367226773137 -0.09144693058051283 -0.023066219276186056" rpy="0 0 0"></origin>
		</collision>
	</link>
	<link name="SphericalWrist1_Link">
		<inertial>
			<origin xyz="1E-06 -0.009432 -0.063883" rpy="0 0 0"></origin>
			<mass value="0.6781"></mass>
			<inertia ixx="0.001596" ixy="0" ixz="0" iyy="0.001607" iyz="0.000256" izz="0.000399"></inertia>
		</inertial>
		<visual>
			<origin xyz="0 0 0" rpy="0 0 0"></origin>
			<geometry>
				<mesh filename="../meshes/spherical_wrist_1_link.STL"></mesh>
			</geometry>
			<material name="">
				<color rgba="0.75294 0.75294 0.75294 1"></color>
			</material>
		</visual>
		<collision>
			<geometry>
				<sphere radius="0.082794"></sphere>
			</geometry>
			<origin xyz="0.0017858616330920273 -0.015578702194958815 -0.06512724873185016" rpy="0 0 0"></origin>
		</collision>
	</link>
	<link name="SphericalWrist2_Link">
		<inertial>
			<origin xyz="1E-06 -0.045483 -0.00965" rpy="0 0 0"></origin>
			<mass value="0.6781"></mass>
			<inertia ixx="0.001641" ixy="0" ixz="0" iyy="0.00041" iyz="-0.000278" izz="0.001641"></inertia>
		</inertial>
		<visual>
			<origin xyz="0 0 0" rpy="0 0 0"></origin>
			<geometry>
				<mesh filename="../meshes/spherical_wrist_2_link.STL"></mesh>
			</geometry>
			<material name="">
				<color rgba="0.75294 0.75294 0.75294 1"></color>
			</material>
		</visual>
		<collision>
			<geometry>
				<sphere radius="0.088179"></sphere>
			</geometry>
			<origin xyz="0.0012520378068379605 -0.046505527081032685 -0.01540443638247195" rpy="0 0 0"></origin>
		</collision>
	</link>
	<link name="Bracelet_Link">
		<inertial>
			<origin xyz="-0.000281 -0.011402 -0.029798" rpy="0 0 0"></origin>
			<mass value="0.5006"></mass>
			<inertia ixx="0.000587" ixy="3E-06" ixz="3E-06" iyy="0.000369" iyz="0.000118" izz="0.000609"></inertia>
		</inertial>
		<visual>
			<origin xyz="0 0 0" rpy="0 0 0"></origin>
			<geometry>
				<mesh filename="../meshes/bracelet_no_vision_link.STL"></mesh>
			</geometry>
			<material name="">
				<color rgba="0.75294 0.75294 0.75294 1"></color>
			</material>
		</visual>
		<collision>
			<geometry>
				<sphere radius="0.052638"></sphere>
			</geometry>
			<origin xyz="-0.00017203373930693044 0.0001731597859556626 -0.030236768550023062" rpy="0 0 0"></origin>
		</collision>
	</link>
	<link name="EndEffector_Link"></link>
	<joint name="Actuator1" type="continuous">
		<origin xyz="0 0 0.15643" rpy="3.1416 2.7629E-18 -4.9305E-36"></origin>
		<parent link="base_link"></parent>
		<child link="Shoulder_Link"></child>
		<axis xyz="0 0 1"></axis>
		<limit effort="39" velocity="0.8727"></limit>
	</joint>
	<joint name="Actuator2" type="revolute">
		<origin xyz="0 0.005375 -0.12838" rpy="1.5708 2.1343E-17 -1.1102E-16"></origin>
		<parent link="Shoulder_Link"></parent>
		<child link="HalfArm1_Link"></child>
		<axis xyz="0 0 1"></axis>
		<limit lower="-2.41" upper="2.41" effort="39" velocity="0.8727"></limit>
	</joint>
	<joint name="Actuator3" type="continuous">
		<origin xyz="0 -0.21038 -0.006375" rpy="-1.5708 1.2326E-32 -2.9122E-16"></origin>
		<parent link="HalfArm1_Link"></parent>
		<child link="HalfArm2_Link"></child>
		<axis xyz="0 0 1"></axis>
		<limit effort="39" velocity="0.8727"></limit>
	</joint>
	<joint name="Actuator4" type="revolute">
		<origin xyz="0 0.006375 -0.21038" rpy="1.5708 -6.6954E-17 -1.6653E-16"></origin>
		<parent link="HalfArm2_Link"></parent>
		<child link="ForeArm_Link"></child>
		<axis xyz="0 0 1"></axis>
		<limit lower="-2.66" upper="2.66" effort="39" velocity="0.8727"></limit>
	</joint>
	<joint name="Actuator5" type="continuous">
		<origin xyz="0 -0.20843 -0.006375" rpy="-1.5708 2.2204E-16 -6.373E-17"></origin>
		<parent link="ForeArm_Link"></parent>
		<child link="SphericalWrist1_Link"></child>
		<axis xyz="0 0 1"></axis>
		<limit effort="9" velocity="0.8727"></limit>
	</joint>
	<joint name="Actuator6" type="revolute">
		<origin xyz="0 0.00017505 -0.10593" rpy="1.5708 9.2076E-28 -8.2157E-15"></origin>
		<parent link="SphericalWrist1_Link"></parent>
		<child link="SphericalWrist2_Link"></child>
		<axis xyz="0 0 1"></axis>
		<limit lower="-2.23" upper="2.23" effort="9" velocity="0.8727"></limit>
	</joint>
	<joint name="Actuator7" type="continuous">
		<origin xyz="0 -0.10593 -0.00017505" rpy="-1.5708 -5.5511E-17 9.6396E-17"></origin>
		<parent link="SphericalWrist2_Link"></parent>
		<child link="Bracelet_Link"></child>
		<axis xyz="0 0 1"></axis>
		<limit effort="9" velocity="0.8727"></limit>
	</joint>
	<joint name="EndEffector" type="fixed">
		<origin xyz="0 0 -0.0615250000000001" rpy="3.14159265358979 1.09937075168372E-32 0"></origin>
		<parent link="Bracelet_Link"></parent>
		<child link="EndEffector_Link"></child>
		<axis xyz="0 0 0"></axis>
	</joint>
</robot>